Workbook

Sheet Inputs
A1: Student loan model — Plan 2 (England)
A2: Yellow cells are inputs — change them and everything recalculates. Figures pre-filled from GOV.UK / SLC / DfE for a Sept 2021 starter.
A4: Your situation
A5: Current salary (gross £/yr) | B5: 48000 | C5: Used for the 9%-above-threshold repayment and the interest-rate taper.
A6: Salary growth (per year, each April) | B6: 0.03 | C6: Applied every April from April 2027.
A7: Voluntary overpayment (£/month) | B7: 0 | C7: Extra you choose to pay monthly, on top of the mandatory amount.
A8: One-off lump sum (£) | B8: 0 | C8: A single extra payment, made in the month below.
A9: Lump sum month | B9: 46388
A10: Known balance override (£) | C10: Optional: your actual balance from your SLC account. Leave blank to use the reconstructed figure. Treated as your balance at April 2026.
A12: Policy assumptions
A13: RPI for interest year Sep 2025 – Aug 2026 | B13: 0.032 | C13: March 2025 RPI. Sets the rate for Apr–Aug 2026.
A14: RPI for interest year Sep 2026 – Aug 2027 | B14: 0.041 | C14: March 2026 RPI (ONS).
A15: Long-run RPI assumption (from Sep 2027) | B15: 0.03 | C15: Your guess for average future inflation.
A16: Interest cap Sep 2026 – Aug 2027 | B16: 0.06 | C16: Government capped Plan 2 interest at 6% for 2026/27.
A17: Long-run interest cap | B17: 1 | C17: 100% = no cap. Lower it to model future caps.
A18: Repayment threshold, 2026-27 (£/yr) | B18: 29385 | C18: You repay 9% of income above this. Also the floor of the interest taper.
A19: Upper interest threshold, 2026-27 (£/yr) | B19: 52885 | C19: Income at which interest reaches RPI+3%.
A20: Thresholds frozen until April | B20: 2030 | C20: Autumn Budget 2025 froze the threshold to end of tax year 2029-30.
A21: Threshold growth after the freeze (per yr) | B21: 0.03 | C21: Applied to both thresholds every April from the year above.
A23: What you borrowed
A24: Academic year | B24: Fee loan £ | C24: Maintenance £ | D24: Note
A25: 2021/22 | B25: 9250 | C25: 4422 | D25: away from home outside London, base rate
A26: 2022/23 | B26: 9250 | C26: 4524 | D26: away from home outside London, base rate
A27: 2023/24 (year abroad) | B27: 1000 | C27: 5524 | D27: your stated fee; overseas base maintenance rate
A28: 2024/25 (final year) | B28: 9250 | C28: 4432 | D28: final-year maintenance rate is slightly lower
A29: Total borrowed | B29: =SUM(B25:B28) | C29: =SUM(C25:C28) | D29: =B29+C29
A31: Historical Plan 2 interest rates (the rate actually charged)
A32: Applies from | B32: Annual rate
A33: 44440 | B33: 0.042
A34: 44470 | B34: 0.041
A35: 44562 | B35: 0.044
A36: 44621 | B36: 0.045
A37: 44805 | B37: 0.063
A38: 44896 | B38: 0.065
A39: 44986 | B39: 0.069
A40: 45078 | B40: 0.071
A41: 45170 | B41: 0.073
A42: 45261 | B42: 0.075
A43: 45292 | B43: 0.076
A44: 45352 | B44: 0.077
...

Sheet Loan build-up
A1: Month | B1: Money drawn down £ | C1: Annual interest rate | D1: Interest added £ | E1: Balance £ | G1: How this sheet works
A2: 44440 | B2: =Inputs!$C$25/3 | C2: =VLOOKUP(A2,Inputs!$A$33:$B$49,2,TRUE) | D2: =0*C2/12 | E2: =0+D2+B2 | G2: Maintenance arrives in three termly instalments (Sep / Jan / Apr); the fee loan is paid to the university termly (Oct 25%, Feb 25%, May 50%). Interest compounds monthly at the historical rate. The final balance feeds the Projection sheet.
A3: 44470 | B3: =Inputs!$B$25*0.25 | C3: =VLOOKUP(A3,Inputs!$A$33:$B$49,2,TRUE) | D3: =E2*C3/12 | E3: =E2+D3+B3
A4: 44501 | B4: 0 | C4: =VLOOKUP(A4,Inputs!$A$33:$B$49,2,TRUE) | D4: =E3*C4/12 | E4: =E3+D4+B4 | G4: Reconstructed balance at April 2026: | H4: =E56
A5: 44531 | B5: 0 | C5: =VLOOKUP(A5,Inputs!$A$33:$B$49,2,TRUE) | D5: =E4*C5/12 | E5: =E4+D5+B5
A6: 44562 | B6: =Inputs!$C$25/3 | C6: =VLOOKUP(A6,Inputs!$A$33:$B$49,2,TRUE) | D6: =E5*C6/12 | E6: =E5+D6+B6
A7: 44593 | B7: =Inputs!$B$25*0.25 | C7: =VLOOKUP(A7,Inputs!$A$33:$B$49,2,TRUE) | D7: =E6*C7/12 | E7: =E6+D7+B7
A8: 44621 | B8: 0 | C8: =VLOOKUP(A8,Inputs!$A$33:$B$49,2,TRUE) | D8: =E7*C8/12 | E8: =E7+D8+B8
A9: 44652 | B9: =Inputs!$C$25/3 | C9: =VLOOKUP(A9,Inputs!$A$33:$B$49,2,TRUE) | D9: =E8*C9/12 | E9: =E8+D9+B9
A10: 44682 | B10: =Inputs!$B$25*0.5 | C10: =VLOOKUP(A10,Inputs!$A$33:$B$49,2,TRUE) | D10: =E9*C10/12 | E10: =E9+D10+B10
A11: 44713 | B11: 0 | C11: =VLOOKUP(A11,Inputs!$A$33:$B$49,2,TRUE) | D11: =E10*C11/12 | E11: =E10+D11+B11
A12: 44743 | B12: 0 | C12: =VLOOKUP(A12,Inputs!$A$33:$B$49,2,TRUE) | D12: =E11*C12/12 | E12: =E11+D12+B12
A13: 44774 | B13: 0 | C13: =VLOOKUP(A13,Inputs!$A$33:$B$49,2,TRUE) | D13: =E12*C13/12 | E13: =E12+D13+B13
A14: 44805 | B14: =Inputs!$C$26/3 | C14: =VLOOKUP(A14,Inputs!$A$33:$B$49,2,TRUE) | D14: =E13*C14/12 | E14: =E13+D14+B14
A15: 44835 | B15: =Inputs!$B$26*0.25 | C15: =VLOOKUP(A15,Inputs!$A$33:$B$49,2,TRUE) | D15: =E14*C15/12 | E15: =E14+D15+B15
A16: 44866 | B16: 0 | C16: =VLOOKUP(A16,Inputs!$A$33:$B$49,2,TRUE) | D16: =E15*C16/12 | E16: =E15+D16+B16
A17: 44896 | B17: 0 | C17: =VLOOKUP(A17,Inputs!$A$33:$B$49,2,TRUE) | D17: =E16*C17/12 | E17: =E16+D17+B17
A18: 44927 | B18: =Inputs!$C$26/3 | C18: =VLOOKUP(A18,Inputs!$A$33:$B$49,2,TRUE) | D18: =E17*C18/12 | E18: =E17+D18+B18
A19: 44958 | B19: =Inputs!$B$26*0.25 | C19: =VLOOKUP(A19,Inputs!$A$33:$B$49,2,TRUE) | D19: =E18*C19/12 | E19: =E18+D19+B19
A20: 44986 | B20: 0 | C20: =VLOOKUP(A20,Inputs!$A$33:$B$49,2,TRUE) | D20: =E19*C20/12 | E20: =E19+D20+B20
A21: 45017 | B21: =Inputs!$C$26/3 | C21: =VLOOKUP(A21,Inputs!$A$33:$B$49,2,TRUE) | D21: =E20*C21/12 | E21: =E20+D21+B21
A22: 45047 | B22: =Inputs!$B$26*0.5 | C22: =VLOOKUP(A22,Inputs!$A$33:$B$49,2,TRUE) | D22: =E21*C22/12 | E22: =E21+D22+B22
A23: 45078 | B23: 0 | C23: =VLOOKUP(A23,Inputs!$A$33:$B$49,2,TRUE) | D23: =E22*C23/12 | E23: =E22+D23+B23
A24: 45108 | B24: 0 | C24: =VLOOKUP(A24,Inputs!$A$33:$B$49,2,TRUE) | D24: =E23*C24/12 | E24: =E23+D24+B24
A25: 45139 | B25: 0 | C25: =VLOOKUP(A25,Inputs!$A$33:$B$49,2,TRUE) | D25: =E24*C25/12 | E25: =E24+D25+B25
A26: 45170 | B26: =Inputs!$C$27/3 | C26: =VLOOKUP(A26,Inputs!$A$33:$B$49,2,TRUE) | D26: =E25*C26/12 | E26: =E25+D26+B26
A27: 45200 | B27: =Inputs!$B$27*0.25 | C27: =VLOOKUP(A27,Inputs!$A$33:$B$49,2,TRUE) | D27: =E26*C27/12 | E27: =E26+D27+B27
A28: 45231 | B28: 0 | C28: =VLOOKUP(A28,Inputs!$A$33:$B$49,2,TRUE) | D28: =E27*C28/12 | E28: =E27+D28+B28
A29: 45261 | B29: 0 | C29: =VLOOKUP(A29,Inputs!$A$33:$B$49,2,TRUE) | D29: =E28*C29/12 | E29: =E28+D29+B29
A30: 45292 | B30: =Inputs!$C$27/3 | C30: =VLOOKUP(A30,Inputs!$A$33:$B$49,2,TRUE) | D30: =E29*C30/12 | E30: =E29+D30+B30
A31: 45323 | B31: =Inputs!$B$27*0.25 | C31: =VLOOKUP(A31,Inputs!$A$33:$B$49,2,TRUE) | D31: =E30*C31/12 | E31: =E30+D31+B31
A32: 45352 | B32: 0 | C32: =VLOOKUP(A32,Inputs!$A$33:$B$49,2,TRUE) | D32: =E31*C32/12 | E32: =E31+D32+B32
A33: 45383 | B33: =Inputs!$C$27/3 | C33: =VLOOKUP(A33,Inputs!$A$33:$B$49,2,TRUE) | D33: =E32*C33/12 | E33: =E32+D33+B33
A34: 45413 | B34: =Inputs!$B$27*0.5 | C34: =VLOOKUP(A34,Inputs!$A$33:$B$49,2,TRUE) | D34: =E33*C34/12 | E34: =E33+D34+B34
A35: 45444 | B35: 0 | C35: =VLOOKUP(A35,Inputs!$A$33:$B$49,2,TRUE) | D35: =E34*C35/12 | E35: =E34+D35+B35
A36: 45474 | B36: 0 | C36: =VLOOKUP(A36,Inputs!$A$33:$B$49,2,TRUE) | D36: =E35*C36/12 | E36: =E35+D36+B36
A37: 45505 | B37: 0 | C37: =VLOOKUP(A37,Inputs!$A$33:$B$49,2,TRUE) | D37: =E36*C37/12 | E37: =E36+D37+B37
A38: 45536 | B38: =Inputs!$C$28/3 | C38: =VLOOKUP(A38,Inputs!$A$33:$B$49,2,TRUE) | D38: =E37*C38/12 | E38: =E37+D38+B38
A39: 45566 | B39: =Inputs!$B$28*0.25 | C39: =VLOOKUP(A39,Inputs!$A$33:$B$49,2,TRUE) | D39: =E38*C39/12 | E39: =E38+D39+B39
A40: 45597 | B40: 0 | C40: =VLOOKUP(A40,Inputs!$A$33:$B$49,2,TRUE) | D40: =E39*C40/12 | E40: =E39+D40+B40
...

Sheet Projection
A1: Month | B1: Salary £/yr | C1: Repayment threshold £/yr | D1: Upper interest threshold £/yr | E1: RPI | F1: Interest cap | G1: Interest rate charged | H1: Mandatory payment £/mo | I1: MANDATORY ONLY — interest £ | J1: MANDATORY ONLY — paid £ | K1: MANDATORY ONLY — balance £ | L1: WITH OVERPAYMENTS — extra paid £ | M1: WITH OVERPAYMENTS — interest £ | N1: WITH OVERPAYMENTS — total paid £ | O1: WITH OVERPAYMENTS — balance £
A2: 46113 | B2: =Inputs!$B$5 | C2: =Inputs!$B$18 | D2: =Inputs!$B$19 | E2: =VLOOKUP(A2,Inputs!$A$53:$C$55,2,TRUE) | F2: =VLOOKUP(A2,Inputs!$A$53:$C$55,3,TRUE) | G2: =MIN(F2,E2+0.03*MAX(0,MIN(1,(B2-C2)/(D2-C2)))) | H2: =MAX(0,0.09*(B2-C2)/12) | I2: =Summary!$B$5*G2/12 | J2: =MIN(H2,Summary!$B$5+I2) | K2: =MAX(0,Summary!$B$5+I2-J2) | L2: =Inputs!$B$7+IF(AND(YEAR(A2)=YEAR(Inputs!$B$9),MONTH(A2)=MONTH(Inputs!$B$9)),Inputs!$B$8,0) | M2: =Summary!$B$5*G2/12 | N2: =MIN(H2+L2,Summary!$B$5+M2) | O2: =MAX(0,Summary!$B$5+M2-N2)
A3: 46143 | B3: =IF(MONTH(A3)=4,B2*(1+Inputs!$B$6),B2) | C3: =IF(AND(MONTH(A3)=4,YEAR(A3)>=Inputs!$B$20),C2*(1+Inputs!$B$21),C2) | D3: =IF(AND(MONTH(A3)=4,YEAR(A3)>=Inputs!$B$20),D2*(1+Inputs!$B$21),D2) | E3: =VLOOKUP(A3,Inputs!$A$53:$C$55,2,TRUE) | F3: =VLOOKUP(A3,Inputs!$A$53:$C$55,3,TRUE) | G3: =MIN(F3,E3+0.03*MAX(0,MIN(1,(B3-C3)/(D3-C3)))) | H3: =MAX(0,0.09*(B3-C3)/12) | I3: =K2*G3/12 | J3: =MIN(H3,K2+I3) | K3: =MAX(0,K2+I3-J3) | L3: =Inputs!$B$7+IF(AND(YEAR(A3)=YEAR(Inputs!$B$9),MONTH(A3)=MONTH(Inputs!$B$9)),Inputs!$B$8,0) | M3: =O2*G3/12 | N3: =MIN(H3+L3,O2+M3) | O3: =MAX(0,O2+M3-N3)
A4: 46174 | B4: =IF(MONTH(A4)=4,B3*(1+Inputs!$B$6),B3) | C4: =IF(AND(MONTH(A4)=4,YEAR(A4)>=Inputs!$B$20),C3*(1+Inputs!$B$21),C3) | D4: =IF(AND(MONTH(A4)=4,YEAR(A4)>=Inputs!$B$20),D3*(1+Inputs!$B$21),D3) | E4: =VLOOKUP(A4,Inputs!$A$53:$C$55,2,TRUE) | F4: =VLOOKUP(A4,Inputs!$A$53:$C$55,3,TRUE) | G4: =MIN(F4,E4+0.03*MAX(0,MIN(1,(B4-C4)/(D4-C4)))) | H4: =MAX(0,0.09*(B4-C4)/12) | I4: =K3*G4/12 | J4: =MIN(H4,K3+I4) | K4: =MAX(0,K3+I4-J4) | L4: =Inputs!$B$7+IF(AND(YEAR(A4)=YEAR(Inputs!$B$9),MONTH(A4)=MONTH(Inputs!$B$9)),Inputs!$B$8,0) | M4: =O3*G4/12 | N4: =MIN(H4+L4,O3+M4) | O4: =MAX(0,O3+M4-N4)
A5: 46204 | B5: =IF(MONTH(A5)=4,B4*(1+Inputs!$B$6),B4) | C5: =IF(AND(MONTH(A5)=4,YEAR(A5)>=Inputs!$B$20),C4*(1+Inputs!$B$21),C4) | D5: =IF(AND(MONTH(A5)=4,YEAR(A5)>=Inputs!$B$20),D4*(1+Inputs!$B$21),D4) | E5: =VLOOKUP(A5,Inputs!$A$53:$C$55,2,TRUE) | F5: =VLOOKUP(A5,Inputs!$A$53:$C$55,3,TRUE) | G5: =MIN(F5,E5+0.03*MAX(0,MIN(1,(B5-C5)/(D5-C5)))) | H5: =MAX(0,0.09*(B5-C5)/12) | I5: =K4*G5/12 | J5: =MIN(H5,K4+I5) | K5: =MAX(0,K4+I5-J5) | L5: =Inputs!$B$7+IF(AND(YEAR(A5)=YEAR(Inputs!$B$9),MONTH(A5)=MONTH(Inputs!$B$9)),Inputs!$B$8,0) | M5: =O4*G5/12 | N5: =MIN(H5+L5,O4+M5) | O5: =MAX(0,O4+M5-N5)
A6: 46235 | B6: =IF(MONTH(A6)=4,B5*(1+Inputs!$B$6),B5) | C6: =IF(AND(MONTH(A6)=4,YEAR(A6)>=Inputs!$B$20),C5*(1+Inputs!$B$21),C5) | D6: =IF(AND(MONTH(A6)=4,YEAR(A6)>=Inputs!$B$20),D5*(1+Inputs!$B$21),D5) | E6: =VLOOKUP(A6,Inputs!$A$53:$C$55,2,TRUE) | F6: =VLOOKUP(A6,Inputs!$A$53:$C$55,3,TRUE) | G6: =MIN(F6,E6+0.03*MAX(0,MIN(1,(B6-C6)/(D6-C6)))) | H6: =MAX(0,0.09*(B6-C6)/12) | I6: =K5*G6/12 | J6: =MIN(H6,K5+I6) | K6: =MAX(0,K5+I6-J6) | L6: =Inputs!$B$7+IF(AND(YEAR(A6)=YEAR(Inputs!$B$9),MONTH(A6)=MONTH(Inputs!$B$9)),Inputs!$B$8,0) | M6: =O5*G6/12 | N6: =MIN(H6+L6,O5+M6) | O6: =MAX(0,O5+M6-N6)
A7: 46266 | B7: =IF(MONTH(A7)=4,B6*(1+Inputs!$B$6),B6) | C7: =IF(AND(MONTH(A7)=4,YEAR(A7)>=Inputs!$B$20),C6*(1+Inputs!$B$21),C6) | D7: =IF(AND(MONTH(A7)=4,YEAR(A7)>=Inputs!$B$20),D6*(1+Inputs!$B$21),D6) | E7: =VLOOKUP(A7,Inputs!$A$53:$C$55,2,TRUE) | F7: =VLOOKUP(A7,Inputs!$A$53:$C$55,3,TRUE) | G7: =MIN(F7,E7+0.03*MAX(0,MIN(1,(B7-C7)/(D7-C7)))) | H7: =MAX(0,0.09*(B7-C7)/12) | I7: =K6*G7/12 | J7: =MIN(H7,K6+I7) | K7: =MAX(0,K6+I7-J7) | L7: =Inputs!$B$7+IF(AND(YEAR(A7)=YEAR(Inputs!$B$9),MONTH(A7)=MONTH(Inputs!$B$9)),Inputs!$B$8,0) | M7: =O6*G7/12 | N7: =MIN(H7+L7,O6+M7) | O7: =MAX(0,O6+M7-N7)
A8: 46296 | B8: =IF(MONTH(A8)=4,B7*(1+Inputs!$B$6),B7) | C8: =IF(AND(MONTH(A8)=4,YEAR(A8)>=Inputs!$B$20),C7*(1+Inputs!$B$21),C7) | D8: =IF(AND(MONTH(A8)=4,YEAR(A8)>=Inputs!$B$20),D7*(1+Inputs!$B$21),D7) | E8: =VLOOKUP(A8,Inputs!$A$53:$C$55,2,TRUE) | F8: =VLOOKUP(A8,Inputs!$A$53:$C$55,3,TRUE) | G8: =MIN(F8,E8+0.03*MAX(0,MIN(1,(B8-C8)/(D8-C8)))) | H8: =MAX(0,0.09*(B8-C8)/12) | I8: =K7*G8/12 | J8: =MIN(H8,K7+I8) | K8: =MAX(0,K7+I8-J8) | L8: =Inputs!$B$7+IF(AND(YEAR(A8)=YEAR(Inputs!$B$9),MONTH(A8)=MONTH(Inputs!$B$9)),Inputs!$B$8,0) | M8: =O7*G8/12 | N8: =MIN(H8+L8,O7+M8) | O8: =MAX(0,O7+M8-N8)
A9: 46327 | B9: =IF(MONTH(A9)=4,B8*(1+Inputs!$B$6),B8) | C9: =IF(AND(MONTH(A9)=4,YEAR(A9)>=Inputs!$B$20),C8*(1+Inputs!$B$21),C8) | D9: =IF(AND(MONTH(A9)=4,YEAR(A9)>=Inputs!$B$20),D8*(1+Inputs!$B$21),D8) | E9: =VLOOKUP(A9,Inputs!$A$53:$C$55,2,TRUE) | F9: =VLOOKUP(A9,Inputs!$A$53:$C$55,3,TRUE) | G9: =MIN(F9,E9+0.03*MAX(0,MIN(1,(B9-C9)/(D9-C9)))) | H9: =MAX(0,0.09*(B9-C9)/12) | I9: =K8*G9/12 | J9: =MIN(H9,K8+I9) | K9: =MAX(0,K8+I9-J9) | L9: =Inputs!$B$7+IF(AND(YEAR(A9)=YEAR(Inputs!$B$9),MONTH(A9)=MONTH(Inputs!$B$9)),Inputs!$B$8,0) | M9: =O8*G9/12 | N9: =MIN(H9+L9,O8+M9) | O9: =MAX(0,O8+M9-N9)
A10: 46357 | B10: =IF(MONTH(A10)=4,B9*(1+Inputs!$B$6),B9) | C10: =IF(AND(MONTH(A10)=4,YEAR(A10)>=Inputs!$B$20),C9*(1+Inputs!$B$21),C9) | D10: =IF(AND(MONTH(A10)=4,YEAR(A10)>=Inputs!$B$20),D9*(1+Inputs!$B$21),D9) | E10: =VLOOKUP(A10,Inputs!$A$53:$C$55,2,TRUE) | F10: =VLOOKUP(A10,Inputs!$A$53:$C$55,3,TRUE) | G10: =MIN(F10,E10+0.03*MAX(0,MIN(1,(B10-C10)/(D10-C10)))) | H10: =MAX(0,0.09*(B10-C10)/12) | I10: =K9*G10/12 | J10: =MIN(H10,K9+I10) | K10: =MAX(0,K9+I10-J10) | L10: =Inputs!$B$7+IF(AND(YEAR(A10)=YEAR(Inputs!$B$9),MONTH(A10)=MONTH(Inputs!$B$9)),Inputs!$B$8,0) | M10: =O9*G10/12 | N10: =MIN(H10+L10,O9+M10) | O10: =MAX(0,O9+M10-N10)
A11: 46388 | B11: =IF(MONTH(A11)=4,B10*(1+Inputs!$B$6),B10) | C11: =IF(AND(MONTH(A11)=4,YEAR(A11)>=Inputs!$B$20),C10*(1+Inputs!$B$21),C10) | D11: =IF(AND(MONTH(A11)=4,YEAR(A11)>=Inputs!$B$20),D10*(1+Inputs!$B$21),D10) | E11: =VLOOKUP(A11,Inputs!$A$53:$C$55,2,TRUE) | F11: =VLOOKUP(A11,Inputs!$A$53:$C$55,3,TRUE) | G11: =MIN(F11,E11+0.03*MAX(0,MIN(1,(B11-C11)/(D11-C11)))) | H11: =MAX(0,0.09*(B11-C11)/12) | I11: =K10*G11/12 | J11: =MIN(H11,K10+I11) | K11: =MAX(0,K10+I11-J11) | L11: =Inputs!$B$7+IF(AND(YEAR(A11)=YEAR(Inputs!$B$9),MONTH(A11)=MONTH(Inputs!$B$9)),Inputs!$B$8,0) | M11: =O10*G11/12 | N11: =MIN(H11+L11,O10+M11) | O11: =MAX(0,O10+M11-N11)
A12: 46419 | B12: =IF(MONTH(A12)=4,B11*(1+Inputs!$B$6),B11) | C12: =IF(AND(MONTH(A12)=4,YEAR(A12)>=Inputs!$B$20),C11*(1+Inputs!$B$21),C11) | D12: =IF(AND(MONTH(A12)=4,YEAR(A12)>=Inputs!$B$20),D11*(1+Inputs!$B$21),D11) | E12: =VLOOKUP(A12,Inputs!$A$53:$C$55,2,TRUE) | F12: =VLOOKUP(A12,Inputs!$A$53:$C$55,3,TRUE) | G12: =MIN(F12,E12+0.03*MAX(0,MIN(1,(B12-C12)/(D12-C12)))) | H12: =MAX(0,0.09*(B12-C12)/12) | I12: =K11*G12/12 | J12: =MIN(H12,K11+I12) | K12: =MAX(0,K11+I12-J12) | L12: =Inputs!$B$7+IF(AND(YEAR(A12)=YEAR(Inputs!$B$9),MONTH(A12)=MONTH(Inputs!$B$9)),Inputs!$B$8,0) | M12: =O11*G12/12 | N12: =MIN(H12+L12,O11+M12) | O12: =MAX(0,O11+M12-N12)
A13: 46447 | B13: =IF(MONTH(A13)=4,B12*(1+Inputs!$B$6),B12) | C13: =IF(AND(MONTH(A13)=4,YEAR(A13)>=Inputs!$B$20),C12*(1+Inputs!$B$21),C12) | D13: =IF(AND(MONTH(A13)=4,YEAR(A13)>=Inputs!$B$20),D12*(1+Inputs!$B$21),D12) | E13: =VLOOKUP(A13,Inputs!$A$53:$C$55,2,TRUE) | F13: =VLOOKUP(A13,Inputs!$A$53:$C$55,3,TRUE) | G13: =MIN(F13,E13+0.03*MAX(0,MIN(1,(B13-C13)/(D13-C13)))) | H13: =MAX(0,0.09*(B13-C13)/12) | I13: =K12*G13/12 | J13: =MIN(H13,K12+I13) | K13: =MAX(0,K12+I13-J13) | L13: =Inputs!$B$7+IF(AND(YEAR(A13)=YEAR(Inputs!$B$9),MONTH(A13)=MONTH(Inputs!$B$9)),Inputs!$B$8,0) | M13: =O12*G13/12 | N13: =MIN(H13+L13,O12+M13) | O13: =MAX(0,O12+M13-N13)
A14: 46478 | B14: =IF(MONTH(A14)=4,B13*(1+Inputs!$B$6),B13) | C14: =IF(AND(MONTH(A14)=4,YEAR(A14)>=Inputs!$B$20),C13*(1+Inputs!$B$21),C13) | D14: =IF(AND(MONTH(A14)=4,YEAR(A14)>=Inputs!$B$20),D13*(1+Inputs!$B$21),D13) | E14: =VLOOKUP(A14,Inputs!$A$53:$C$55,2,TRUE) | F14: =VLOOKUP(A14,Inputs!$A$53:$C$55,3,TRUE) | G14: =MIN(F14,E14+0.03*MAX(0,MIN(1,(B14-C14)/(D14-C14)))) | H14: =MAX(0,0.09*(B14-C14)/12) | I14: =K13*G14/12 | J14: =MIN(H14,K13+I14) | K14: =MAX(0,K13+I14-J14) | L14: =Inputs!$B$7+IF(AND(YEAR(A14)=YEAR(Inputs!$B$9),MONTH(A14)=MONTH(Inputs!$B$9)),Inputs!$B$8,0) | M14: =O13*G14/12 | N14: =MIN(H14+L14,O13+M14) | O14: =MAX(0,O13+M14-N14)
... A361: 57040 | B361: =IF(MONTH(A361)=4,B360*(1+Inputs!$B$6),B360) | C361: =IF(AND(MONTH(A361)=4,YEAR(A361)>=Inputs!$B$20),C360*(1+Inputs!$B$21),C360) | D361: =IF(AND(MONTH(A361)=4,YEAR(A361)>=Inputs!$B$20),D360*(1+Inputs!$B$21),D360) | E361: =VLOOKUP(A361,Inputs!$A$53:$C$55,2,TRUE) | F361: =VLOOKUP(A361,Inputs!$A$53:$C$55,3,TRUE) | G361: =MIN(F361,E361+0.03*MAX(0,MIN(1,(B361-C361)/(D361-C361)))) | H361: =MAX(0,0.09*(B361-C361)/12) | I361: =K360*G361/12 | J361: =MIN(H361,K360+I361) | K361: =MAX(0,K360+I361-J361) | L361: =Inputs!$B$7+IF(AND(YEAR(A361)=YEAR(Inputs!$B$9),MONTH(A361)=MONTH(Inputs!$B$9)),Inputs!$B$8,0) | M361: =O360*G361/12 | N361: =MIN(H361+L361,O360+M361) | O361: =MAX(0,O360+M361-N361)

Sheet Summary
A1: Summary
A2: All figures recalculate from the Inputs sheet.
A4: Total borrowed 2021–2025 | B4: =Inputs!D29
A5: Balance at April 2026 (repayments start) | B5: =IF(N(Inputs!B10)>0,Inputs!B10,'Loan build-up'!E56) | C5: Uses your SLC override if entered on Inputs, else the reconstruction.
A6: Interest added while studying | B6: =SUM('Loan build-up'!D2:D56)
A7: First mandatory payment (£/month) | B7: =Projection!H2
A9: The two scenarios (April 2026 → April 2056 write-off)
B10: Mandatory only | C10: With overpayments
A11: Paid off in | B11: =IFERROR(TEXT(INDEX(Projection!$A$2:$A$361,MATCH(0,Projection!$K$2:$K$361,0)),"mmm yyyy"),"Never — written off Apr 2056") | C11: =IFERROR(TEXT(INDEX(Projection!$A$2:$A$361,MATCH(0,Projection!$O$2:$O$361,0)),"mmm yyyy"),"Never — written off Apr 2056")
A12: Total you pay | B12: =SUM(Projection!J2:J361) | C12: =SUM(Projection!N2:N361)
A13: Interest charged after uni | B13: =SUM(Projection!I2:I361) | C13: =SUM(Projection!M2:M361)
A14: Written off at April 2056 | B14: =Projection!K361 | C14: =Projection!O361
A16: Overpaying changes your total cost by | B16: =C12-B12 | C16: Negative = overpaying saves you money overall; positive = you pay more in total than just waiting for the write-off.
